{
 "cells": [
  {
   "cell_type": "code",
   "execution_count": null,
   "metadata": {},
   "outputs": [
    {
     "ename": "",
     "evalue": "",
     "output_type": "error",
     "traceback": [
      "\u001b[1;31mFailed to start the Kernel. \n",
      "\u001b[1;31mTraceback (most recent call last):\n",
      "\u001b[1;31m  File \"/Users/mathieuboudreau/.pyenv/versions/3.7.10/lib/python3.7/site-packages/traitlets/config/application.py\", line 107, in inner\n",
      "\u001b[1;31m    return method(app, *args, **kwargs)\n",
      "\u001b[1;31m  File \"/Users/mathieuboudreau/.pyenv/versions/3.7.10/lib/python3.7/site-packages/traitlets/config/application.py\", line 816, in parse_command_line\n",
      "\u001b[1;31m    self.update_config(self.cli_config)\n",
      "\u001b[1;31m  File \"/Users/mathieuboudreau/.pyenv/versions/3.7.10/lib/python3.7/site-packages/traitlets/config/configurable.py\", line 230, in update_config\n",
      "\u001b[1;31m    self._load_config(config)\n",
      "\u001b[1;31m  File \"/Users/mathieuboudreau/.pyenv/versions/3.7.10/lib/python3.7/site-packages/traitlets/config/configurable.py\", line 200, in _load_config\n",
      "\u001b[1;31m    warn(msg)\n",
      "\u001b[1;31m  File \"/Users/mathieuboudreau/.pyenv/versions/3.7.10/lib/python3.7/contextlib.py\", line 119, in __exit__\n",
      "\u001b[1;31m    next(self.gen)\n",
      "\u001b[1;31m  File \"/Users/mathieuboudreau/.pyenv/versions/3.7.10/lib/python3.7/site-packages/traitlets/traitlets.py\", line 1359, in hold_trait_notifications\n",
      "\u001b[1;31m    raise e\n",
      "\u001b[1;31m  File \"/Users/mathieuboudreau/.pyenv/versions/3.7.10/lib/python3.7/site-packages/traitlets/traitlets.py\", line 1345, in hold_trait_notifications\n",
      "\u001b[1;31m    value = trait._cross_validate(self, getattr(self, name))\n",
      "\u001b[1;31m  File \"/Users/mathieuboudreau/.pyenv/versions/3.7.10/lib/python3.7/site-packages/traitlets/traitlets.py\", line 726, in _cross_validate\n",
      "\u001b[1;31m    value = obj._trait_validators<a href='obj, proposal'>self.name</a>\n",
      "\u001b[1;31m  File \"/Users/mathieuboudreau/.pyenv/versions/3.7.10/lib/python3.7/site-packages/traitlets/traitlets.py\", line 1129, in __call__\n",
      "\u001b[1;31m    return self.func(*args, **kwargs)\n",
      "\u001b[1;31m  File \"/Users/mathieuboudreau/.pyenv/versions/3.7.10/lib/python3.7/site-packages/notebook/notebookapp.py\", line 1522, in _notebook_dir_validate\n",
      "\u001b[1;31m    raise TraitError(trans.gettext(\"No such notebook dir: '%r'\") % value)\n",
      "\u001b[1;31mtraitlets.traitlets.TraitError: No such notebook dir: ''/Users/mathieuboudreau/neuropoly/fun/advent/01-1''\n",
      "\u001b[1;31m\n",
      "\u001b[1;31mDuring handling of the above exception, another exception occurred:\n",
      "\u001b[1;31m\n",
      "\u001b[1;31mTraceback (most recent call last):\n",
      "\u001b[1;31m  File \"/Users/mathieuboudreau/.vscode/extensions/ms-toolsai.jupyter-2022.9.1303220346/pythonFiles/vscode_datascience_helpers/daemon/daemon_python.py\", line 54, in _decorator\n",
      "\u001b[1;31m    return func(self, *args, **kwargs)\n",
      "\u001b[1;31m  File \"/Users/mathieuboudreau/.vscode/extensions/ms-toolsai.jupyter-2022.9.1303220346/pythonFiles/vscode_datascience_helpers/jupyter_daemon.py\", line 111, in m_exec_module_observable\n",
      "\u001b[1;31m    self._start_notebook(args, cwd, env)\n",
      "\u001b[1;31m  File \"/Users/mathieuboudreau/.vscode/extensions/ms-toolsai.jupyter-2022.9.1303220346/pythonFiles/vscode_datascience_helpers/jupyter_daemon.py\", line 168, in _start_notebook\n",
      "\u001b[1;31m    app.launch_new_instance()\n",
      "\u001b[1;31m  File \"/Users/mathieuboudreau/.pyenv/versions/3.7.10/lib/python3.7/site-packages/jupyter_core/application.py\", line 269, in launch_instance\n",
      "\u001b[1;31m    return super().launch_instance(argv=argv, **kwargs)\n",
      "\u001b[1;31m  File \"/Users/mathieuboudreau/.pyenv/versions/3.7.10/lib/python3.7/site-packages/traitlets/config/application.py\", line 971, in launch_instance\n",
      "\u001b[1;31m    app.initialize(argv)\n",
      "\u001b[1;31m  File \"/Users/mathieuboudreau/.pyenv/versions/3.7.10/lib/python3.7/site-packages/traitlets/config/application.py\", line 107, in inner\n",
      "\u001b[1;31m    return method(app, *args, **kwargs)\n",
      "\u001b[1;31m  File \"/Users/mathieuboudreau/.pyenv/versions/3.7.10/lib/python3.7/site-packages/notebook/notebookapp.py\", line 2141, in initialize\n",
      "\u001b[1;31m    super().initialize(argv)\n",
      "\u001b[1;31m  File \"/Users/mathieuboudreau/.pyenv/versions/3.7.10/lib/python3.7/site-packages/traitlets/config/application.py\", line 107, in inner\n",
      "\u001b[1;31m    return method(app, *args, **kwargs)\n",
      "\u001b[1;31m  File \"/Users/mathieuboudreau/.pyenv/versions/3.7.10/lib/python3.7/site-packages/jupyter_core/application.py\", line 240, in initialize\n",
      "\u001b[1;31m    self.parse_command_line(argv)\n",
      "\u001b[1;31m  File \"/Users/mathieuboudreau/.pyenv/versions/3.7.10/lib/python3.7/site-packages/notebook/notebookapp.py\", line 1611, in parse_command_line\n",
      "\u001b[1;31m    super().parse_command_line(argv)\n",
      "\u001b[1;31m  File \"/Users/mathieuboudreau/.pyenv/versions/3.7.10/lib/python3.7/site-packages/traitlets/config/application.py\", line 111, in inner\n",
      "\u001b[1;31m    app.exit(1)\n",
      "\u001b[1;31m  File \"/Users/mathieuboudreau/.pyenv/versions/3.7.10/lib/python3.7/site-packages/traitlets/config/application.py\", line 959, in exit\n",
      "\u001b[1;31m    sys.exit(exit_status)\n",
      "\u001b[1;31mSystemExit: 1\n",
      "\u001b[1;31m\n",
      "\u001b[1;31m[C 01:05:47.790 NotebookApp] Bad config encountered during initialization: No such notebook dir: ''/Users/mathieuboudreau/neuropoly/fun/advent/01-1''\n",
      "\u001b[1;31m\n",
      "\u001b[1;31mFailed to run jupyter as observable with args notebook --no-browser --notebook-dir=\"/Users/mathieuboudreau/neuropoly/fun/advent/01-1\" --config=/var/folders/l1/1xswjffd73l8yp7dd7pq9lyw0000gn/T/aa7f2ece-3d62-4baf-ae26-3dd5604cf53a/jupyter_notebook_config.py --NotebookApp.iopub_data_rate_limit=10000000000.0"
     ]
    }
   ],
   "source": [
    "## Imports\n",
    "import os"
   ]
  },
  {
   "cell_type": "code",
   "execution_count": null,
   "metadata": {},
   "outputs": [
    {
     "ename": "",
     "evalue": "",
     "output_type": "error",
     "traceback": [
      "\u001b[1;31mFailed to start the Kernel. \n",
      "\u001b[1;31mTraceback (most recent call last):\n",
      "\u001b[1;31m  File \"/Users/mathieuboudreau/.pyenv/versions/3.7.10/lib/python3.7/site-packages/traitlets/config/application.py\", line 107, in inner\n",
      "\u001b[1;31m    return method(app, *args, **kwargs)\n",
      "\u001b[1;31m  File \"/Users/mathieuboudreau/.pyenv/versions/3.7.10/lib/python3.7/site-packages/traitlets/config/application.py\", line 816, in parse_command_line\n",
      "\u001b[1;31m    self.update_config(self.cli_config)\n",
      "\u001b[1;31m  File \"/Users/mathieuboudreau/.pyenv/versions/3.7.10/lib/python3.7/site-packages/traitlets/config/configurable.py\", line 230, in update_config\n",
      "\u001b[1;31m    self._load_config(config)\n",
      "\u001b[1;31m  File \"/Users/mathieuboudreau/.pyenv/versions/3.7.10/lib/python3.7/site-packages/traitlets/config/configurable.py\", line 200, in _load_config\n",
      "\u001b[1;31m    warn(msg)\n",
      "\u001b[1;31m  File \"/Users/mathieuboudreau/.pyenv/versions/3.7.10/lib/python3.7/contextlib.py\", line 119, in __exit__\n",
      "\u001b[1;31m    next(self.gen)\n",
      "\u001b[1;31m  File \"/Users/mathieuboudreau/.pyenv/versions/3.7.10/lib/python3.7/site-packages/traitlets/traitlets.py\", line 1359, in hold_trait_notifications\n",
      "\u001b[1;31m    raise e\n",
      "\u001b[1;31m  File \"/Users/mathieuboudreau/.pyenv/versions/3.7.10/lib/python3.7/site-packages/traitlets/traitlets.py\", line 1345, in hold_trait_notifications\n",
      "\u001b[1;31m    value = trait._cross_validate(self, getattr(self, name))\n",
      "\u001b[1;31m  File \"/Users/mathieuboudreau/.pyenv/versions/3.7.10/lib/python3.7/site-packages/traitlets/traitlets.py\", line 726, in _cross_validate\n",
      "\u001b[1;31m    value = obj._trait_validators<a href='obj, proposal'>self.name</a>\n",
      "\u001b[1;31m  File \"/Users/mathieuboudreau/.pyenv/versions/3.7.10/lib/python3.7/site-packages/traitlets/traitlets.py\", line 1129, in __call__\n",
      "\u001b[1;31m    return self.func(*args, **kwargs)\n",
      "\u001b[1;31m  File \"/Users/mathieuboudreau/.pyenv/versions/3.7.10/lib/python3.7/site-packages/notebook/notebookapp.py\", line 1522, in _notebook_dir_validate\n",
      "\u001b[1;31m    raise TraitError(trans.gettext(\"No such notebook dir: '%r'\") % value)\n",
      "\u001b[1;31mtraitlets.traitlets.TraitError: No such notebook dir: ''/Users/mathieuboudreau/neuropoly/fun/advent/01-1''\n",
      "\u001b[1;31m\n",
      "\u001b[1;31mDuring handling of the above exception, another exception occurred:\n",
      "\u001b[1;31m\n",
      "\u001b[1;31mTraceback (most recent call last):\n",
      "\u001b[1;31m  File \"/Users/mathieuboudreau/.vscode/extensions/ms-toolsai.jupyter-2022.9.1303220346/pythonFiles/vscode_datascience_helpers/daemon/daemon_python.py\", line 54, in _decorator\n",
      "\u001b[1;31m    return func(self, *args, **kwargs)\n",
      "\u001b[1;31m  File \"/Users/mathieuboudreau/.vscode/extensions/ms-toolsai.jupyter-2022.9.1303220346/pythonFiles/vscode_datascience_helpers/jupyter_daemon.py\", line 111, in m_exec_module_observable\n",
      "\u001b[1;31m    self._start_notebook(args, cwd, env)\n",
      "\u001b[1;31m  File \"/Users/mathieuboudreau/.vscode/extensions/ms-toolsai.jupyter-2022.9.1303220346/pythonFiles/vscode_datascience_helpers/jupyter_daemon.py\", line 168, in _start_notebook\n",
      "\u001b[1;31m    app.launch_new_instance()\n",
      "\u001b[1;31m  File \"/Users/mathieuboudreau/.pyenv/versions/3.7.10/lib/python3.7/site-packages/jupyter_core/application.py\", line 269, in launch_instance\n",
      "\u001b[1;31m    return super().launch_instance(argv=argv, **kwargs)\n",
      "\u001b[1;31m  File \"/Users/mathieuboudreau/.pyenv/versions/3.7.10/lib/python3.7/site-packages/traitlets/config/application.py\", line 971, in launch_instance\n",
      "\u001b[1;31m    app.initialize(argv)\n",
      "\u001b[1;31m  File \"/Users/mathieuboudreau/.pyenv/versions/3.7.10/lib/python3.7/site-packages/traitlets/config/application.py\", line 107, in inner\n",
      "\u001b[1;31m    return method(app, *args, **kwargs)\n",
      "\u001b[1;31m  File \"/Users/mathieuboudreau/.pyenv/versions/3.7.10/lib/python3.7/site-packages/notebook/notebookapp.py\", line 2141, in initialize\n",
      "\u001b[1;31m    super().initialize(argv)\n",
      "\u001b[1;31m  File \"/Users/mathieuboudreau/.pyenv/versions/3.7.10/lib/python3.7/site-packages/traitlets/config/application.py\", line 107, in inner\n",
      "\u001b[1;31m    return method(app, *args, **kwargs)\n",
      "\u001b[1;31m  File \"/Users/mathieuboudreau/.pyenv/versions/3.7.10/lib/python3.7/site-packages/jupyter_core/application.py\", line 240, in initialize\n",
      "\u001b[1;31m    self.parse_command_line(argv)\n",
      "\u001b[1;31m  File \"/Users/mathieuboudreau/.pyenv/versions/3.7.10/lib/python3.7/site-packages/notebook/notebookapp.py\", line 1611, in parse_command_line\n",
      "\u001b[1;31m    super().parse_command_line(argv)\n",
      "\u001b[1;31m  File \"/Users/mathieuboudreau/.pyenv/versions/3.7.10/lib/python3.7/site-packages/traitlets/config/application.py\", line 111, in inner\n",
      "\u001b[1;31m    app.exit(1)\n",
      "\u001b[1;31m  File \"/Users/mathieuboudreau/.pyenv/versions/3.7.10/lib/python3.7/site-packages/traitlets/config/application.py\", line 959, in exit\n",
      "\u001b[1;31m    sys.exit(exit_status)\n",
      "\u001b[1;31mSystemExit: 1\n",
      "\u001b[1;31m\n",
      "\u001b[1;31m[C 01:05:47.790 NotebookApp] Bad config encountered during initialization: No such notebook dir: ''/Users/mathieuboudreau/neuropoly/fun/advent/01-1''\n",
      "\u001b[1;31m\n",
      "\u001b[1;31mFailed to run jupyter as observable with args notebook --no-browser --notebook-dir=\"/Users/mathieuboudreau/neuropoly/fun/advent/01-1\" --config=/var/folders/l1/1xswjffd73l8yp7dd7pq9lyw0000gn/T/aa7f2ece-3d62-4baf-ae26-3dd5604cf53a/jupyter_notebook_config.py --NotebookApp.iopub_data_rate_limit=10000000000.0"
     ]
    }
   ],
   "source": [
    "## Read input\n",
    "lines = open('input.txt').read().splitlines()"
   ]
  },
  {
   "cell_type": "code",
   "execution_count": null,
   "metadata": {},
   "outputs": [
    {
     "ename": "",
     "evalue": "",
     "output_type": "error",
     "traceback": [
      "\u001b[1;31mFailed to start the Kernel. \n",
      "\u001b[1;31mTraceback (most recent call last):\n",
      "\u001b[1;31m  File \"/Users/mathieuboudreau/.pyenv/versions/3.7.10/lib/python3.7/site-packages/traitlets/config/application.py\", line 107, in inner\n",
      "\u001b[1;31m    return method(app, *args, **kwargs)\n",
      "\u001b[1;31m  File \"/Users/mathieuboudreau/.pyenv/versions/3.7.10/lib/python3.7/site-packages/traitlets/config/application.py\", line 816, in parse_command_line\n",
      "\u001b[1;31m    self.update_config(self.cli_config)\n",
      "\u001b[1;31m  File \"/Users/mathieuboudreau/.pyenv/versions/3.7.10/lib/python3.7/site-packages/traitlets/config/configurable.py\", line 230, in update_config\n",
      "\u001b[1;31m    self._load_config(config)\n",
      "\u001b[1;31m  File \"/Users/mathieuboudreau/.pyenv/versions/3.7.10/lib/python3.7/site-packages/traitlets/config/configurable.py\", line 200, in _load_config\n",
      "\u001b[1;31m    warn(msg)\n",
      "\u001b[1;31m  File \"/Users/mathieuboudreau/.pyenv/versions/3.7.10/lib/python3.7/contextlib.py\", line 119, in __exit__\n",
      "\u001b[1;31m    next(self.gen)\n",
      "\u001b[1;31m  File \"/Users/mathieuboudreau/.pyenv/versions/3.7.10/lib/python3.7/site-packages/traitlets/traitlets.py\", line 1359, in hold_trait_notifications\n",
      "\u001b[1;31m    raise e\n",
      "\u001b[1;31m  File \"/Users/mathieuboudreau/.pyenv/versions/3.7.10/lib/python3.7/site-packages/traitlets/traitlets.py\", line 1345, in hold_trait_notifications\n",
      "\u001b[1;31m    value = trait._cross_validate(self, getattr(self, name))\n",
      "\u001b[1;31m  File \"/Users/mathieuboudreau/.pyenv/versions/3.7.10/lib/python3.7/site-packages/traitlets/traitlets.py\", line 726, in _cross_validate\n",
      "\u001b[1;31m    value = obj._trait_validators<a href='obj, proposal'>self.name</a>\n",
      "\u001b[1;31m  File \"/Users/mathieuboudreau/.pyenv/versions/3.7.10/lib/python3.7/site-packages/traitlets/traitlets.py\", line 1129, in __call__\n",
      "\u001b[1;31m    return self.func(*args, **kwargs)\n",
      "\u001b[1;31m  File \"/Users/mathieuboudreau/.pyenv/versions/3.7.10/lib/python3.7/site-packages/notebook/notebookapp.py\", line 1522, in _notebook_dir_validate\n",
      "\u001b[1;31m    raise TraitError(trans.gettext(\"No such notebook dir: '%r'\") % value)\n",
      "\u001b[1;31mtraitlets.traitlets.TraitError: No such notebook dir: ''/Users/mathieuboudreau/neuropoly/fun/advent/01-1''\n",
      "\u001b[1;31m\n",
      "\u001b[1;31mDuring handling of the above exception, another exception occurred:\n",
      "\u001b[1;31m\n",
      "\u001b[1;31mTraceback (most recent call last):\n",
      "\u001b[1;31m  File \"/Users/mathieuboudreau/.vscode/extensions/ms-toolsai.jupyter-2022.9.1303220346/pythonFiles/vscode_datascience_helpers/daemon/daemon_python.py\", line 54, in _decorator\n",
      "\u001b[1;31m    return func(self, *args, **kwargs)\n",
      "\u001b[1;31m  File \"/Users/mathieuboudreau/.vscode/extensions/ms-toolsai.jupyter-2022.9.1303220346/pythonFiles/vscode_datascience_helpers/jupyter_daemon.py\", line 111, in m_exec_module_observable\n",
      "\u001b[1;31m    self._start_notebook(args, cwd, env)\n",
      "\u001b[1;31m  File \"/Users/mathieuboudreau/.vscode/extensions/ms-toolsai.jupyter-2022.9.1303220346/pythonFiles/vscode_datascience_helpers/jupyter_daemon.py\", line 168, in _start_notebook\n",
      "\u001b[1;31m    app.launch_new_instance()\n",
      "\u001b[1;31m  File \"/Users/mathieuboudreau/.pyenv/versions/3.7.10/lib/python3.7/site-packages/jupyter_core/application.py\", line 269, in launch_instance\n",
      "\u001b[1;31m    return super().launch_instance(argv=argv, **kwargs)\n",
      "\u001b[1;31m  File \"/Users/mathieuboudreau/.pyenv/versions/3.7.10/lib/python3.7/site-packages/traitlets/config/application.py\", line 971, in launch_instance\n",
      "\u001b[1;31m    app.initialize(argv)\n",
      "\u001b[1;31m  File \"/Users/mathieuboudreau/.pyenv/versions/3.7.10/lib/python3.7/site-packages/traitlets/config/application.py\", line 107, in inner\n",
      "\u001b[1;31m    return method(app, *args, **kwargs)\n",
      "\u001b[1;31m  File \"/Users/mathieuboudreau/.pyenv/versions/3.7.10/lib/python3.7/site-packages/notebook/notebookapp.py\", line 2141, in initialize\n",
      "\u001b[1;31m    super().initialize(argv)\n",
      "\u001b[1;31m  File \"/Users/mathieuboudreau/.pyenv/versions/3.7.10/lib/python3.7/site-packages/traitlets/config/application.py\", line 107, in inner\n",
      "\u001b[1;31m    return method(app, *args, **kwargs)\n",
      "\u001b[1;31m  File \"/Users/mathieuboudreau/.pyenv/versions/3.7.10/lib/python3.7/site-packages/jupyter_core/application.py\", line 240, in initialize\n",
      "\u001b[1;31m    self.parse_command_line(argv)\n",
      "\u001b[1;31m  File \"/Users/mathieuboudreau/.pyenv/versions/3.7.10/lib/python3.7/site-packages/notebook/notebookapp.py\", line 1611, in parse_command_line\n",
      "\u001b[1;31m    super().parse_command_line(argv)\n",
      "\u001b[1;31m  File \"/Users/mathieuboudreau/.pyenv/versions/3.7.10/lib/python3.7/site-packages/traitlets/config/application.py\", line 111, in inner\n",
      "\u001b[1;31m    app.exit(1)\n",
      "\u001b[1;31m  File \"/Users/mathieuboudreau/.pyenv/versions/3.7.10/lib/python3.7/site-packages/traitlets/config/application.py\", line 959, in exit\n",
      "\u001b[1;31m    sys.exit(exit_status)\n",
      "\u001b[1;31mSystemExit: 1\n",
      "\u001b[1;31m\n",
      "\u001b[1;31m[C 01:05:47.790 NotebookApp] Bad config encountered during initialization: No such notebook dir: ''/Users/mathieuboudreau/neuropoly/fun/advent/01-1''\n",
      "\u001b[1;31m\n",
      "\u001b[1;31mFailed to run jupyter as observable with args notebook --no-browser --notebook-dir=\"/Users/mathieuboudreau/neuropoly/fun/advent/01-1\" --config=/var/folders/l1/1xswjffd73l8yp7dd7pq9lyw0000gn/T/aa7f2ece-3d62-4baf-ae26-3dd5604cf53a/jupyter_notebook_config.py --NotebookApp.iopub_data_rate_limit=10000000000.0"
     ]
    }
   ],
   "source": [
    "## Calculate\n",
    "cur_sum = 0\n",
    "max_sums = [0,0,0]\n",
    "for line in lines:\n",
    "    if line == '':\n",
    "        if cur_sum > min(max_sums):\n",
    "            max_sums.append(cur_sum)\n",
    "            max_sums.sort()\n",
    "            max_sums = max_sums[-3:]\n",
    "        cur_sum = 0\n",
    "    else:\n",
    "        cur_sum = cur_sum+int(line)"
   ]
  },
  {
   "cell_type": "code",
   "execution_count": null,
   "metadata": {},
   "outputs": [
    {
     "ename": "",
     "evalue": "",
     "output_type": "error",
     "traceback": [
      "\u001b[1;31mFailed to start the Kernel. \n",
      "\u001b[1;31mTraceback (most recent call last):\n",
      "\u001b[1;31m  File \"/Users/mathieuboudreau/.pyenv/versions/3.7.10/lib/python3.7/site-packages/traitlets/config/application.py\", line 107, in inner\n",
      "\u001b[1;31m    return method(app, *args, **kwargs)\n",
      "\u001b[1;31m  File \"/Users/mathieuboudreau/.pyenv/versions/3.7.10/lib/python3.7/site-packages/traitlets/config/application.py\", line 816, in parse_command_line\n",
      "\u001b[1;31m    self.update_config(self.cli_config)\n",
      "\u001b[1;31m  File \"/Users/mathieuboudreau/.pyenv/versions/3.7.10/lib/python3.7/site-packages/traitlets/config/configurable.py\", line 230, in update_config\n",
      "\u001b[1;31m    self._load_config(config)\n",
      "\u001b[1;31m  File \"/Users/mathieuboudreau/.pyenv/versions/3.7.10/lib/python3.7/site-packages/traitlets/config/configurable.py\", line 200, in _load_config\n",
      "\u001b[1;31m    warn(msg)\n",
      "\u001b[1;31m  File \"/Users/mathieuboudreau/.pyenv/versions/3.7.10/lib/python3.7/contextlib.py\", line 119, in __exit__\n",
      "\u001b[1;31m    next(self.gen)\n",
      "\u001b[1;31m  File \"/Users/mathieuboudreau/.pyenv/versions/3.7.10/lib/python3.7/site-packages/traitlets/traitlets.py\", line 1359, in hold_trait_notifications\n",
      "\u001b[1;31m    raise e\n",
      "\u001b[1;31m  File \"/Users/mathieuboudreau/.pyenv/versions/3.7.10/lib/python3.7/site-packages/traitlets/traitlets.py\", line 1345, in hold_trait_notifications\n",
      "\u001b[1;31m    value = trait._cross_validate(self, getattr(self, name))\n",
      "\u001b[1;31m  File \"/Users/mathieuboudreau/.pyenv/versions/3.7.10/lib/python3.7/site-packages/traitlets/traitlets.py\", line 726, in _cross_validate\n",
      "\u001b[1;31m    value = obj._trait_validators<a href='obj, proposal'>self.name</a>\n",
      "\u001b[1;31m  File \"/Users/mathieuboudreau/.pyenv/versions/3.7.10/lib/python3.7/site-packages/traitlets/traitlets.py\", line 1129, in __call__\n",
      "\u001b[1;31m    return self.func(*args, **kwargs)\n",
      "\u001b[1;31m  File \"/Users/mathieuboudreau/.pyenv/versions/3.7.10/lib/python3.7/site-packages/notebook/notebookapp.py\", line 1522, in _notebook_dir_validate\n",
      "\u001b[1;31m    raise TraitError(trans.gettext(\"No such notebook dir: '%r'\") % value)\n",
      "\u001b[1;31mtraitlets.traitlets.TraitError: No such notebook dir: ''/Users/mathieuboudreau/neuropoly/fun/advent/01-1''\n",
      "\u001b[1;31m\n",
      "\u001b[1;31mDuring handling of the above exception, another exception occurred:\n",
      "\u001b[1;31m\n",
      "\u001b[1;31mTraceback (most recent call last):\n",
      "\u001b[1;31m  File \"/Users/mathieuboudreau/.vscode/extensions/ms-toolsai.jupyter-2022.9.1303220346/pythonFiles/vscode_datascience_helpers/daemon/daemon_python.py\", line 54, in _decorator\n",
      "\u001b[1;31m    return func(self, *args, **kwargs)\n",
      "\u001b[1;31m  File \"/Users/mathieuboudreau/.vscode/extensions/ms-toolsai.jupyter-2022.9.1303220346/pythonFiles/vscode_datascience_helpers/jupyter_daemon.py\", line 111, in m_exec_module_observable\n",
      "\u001b[1;31m    self._start_notebook(args, cwd, env)\n",
      "\u001b[1;31m  File \"/Users/mathieuboudreau/.vscode/extensions/ms-toolsai.jupyter-2022.9.1303220346/pythonFiles/vscode_datascience_helpers/jupyter_daemon.py\", line 168, in _start_notebook\n",
      "\u001b[1;31m    app.launch_new_instance()\n",
      "\u001b[1;31m  File \"/Users/mathieuboudreau/.pyenv/versions/3.7.10/lib/python3.7/site-packages/jupyter_core/application.py\", line 269, in launch_instance\n",
      "\u001b[1;31m    return super().launch_instance(argv=argv, **kwargs)\n",
      "\u001b[1;31m  File \"/Users/mathieuboudreau/.pyenv/versions/3.7.10/lib/python3.7/site-packages/traitlets/config/application.py\", line 971, in launch_instance\n",
      "\u001b[1;31m    app.initialize(argv)\n",
      "\u001b[1;31m  File \"/Users/mathieuboudreau/.pyenv/versions/3.7.10/lib/python3.7/site-packages/traitlets/config/application.py\", line 107, in inner\n",
      "\u001b[1;31m    return method(app, *args, **kwargs)\n",
      "\u001b[1;31m  File \"/Users/mathieuboudreau/.pyenv/versions/3.7.10/lib/python3.7/site-packages/notebook/notebookapp.py\", line 2141, in initialize\n",
      "\u001b[1;31m    super().initialize(argv)\n",
      "\u001b[1;31m  File \"/Users/mathieuboudreau/.pyenv/versions/3.7.10/lib/python3.7/site-packages/traitlets/config/application.py\", line 107, in inner\n",
      "\u001b[1;31m    return method(app, *args, **kwargs)\n",
      "\u001b[1;31m  File \"/Users/mathieuboudreau/.pyenv/versions/3.7.10/lib/python3.7/site-packages/jupyter_core/application.py\", line 240, in initialize\n",
      "\u001b[1;31m    self.parse_command_line(argv)\n",
      "\u001b[1;31m  File \"/Users/mathieuboudreau/.pyenv/versions/3.7.10/lib/python3.7/site-packages/notebook/notebookapp.py\", line 1611, in parse_command_line\n",
      "\u001b[1;31m    super().parse_command_line(argv)\n",
      "\u001b[1;31m  File \"/Users/mathieuboudreau/.pyenv/versions/3.7.10/lib/python3.7/site-packages/traitlets/config/application.py\", line 111, in inner\n",
      "\u001b[1;31m    app.exit(1)\n",
      "\u001b[1;31m  File \"/Users/mathieuboudreau/.pyenv/versions/3.7.10/lib/python3.7/site-packages/traitlets/config/application.py\", line 959, in exit\n",
      "\u001b[1;31m    sys.exit(exit_status)\n",
      "\u001b[1;31mSystemExit: 1\n",
      "\u001b[1;31m\n",
      "\u001b[1;31m[C 01:05:47.790 NotebookApp] Bad config encountered during initialization: No such notebook dir: ''/Users/mathieuboudreau/neuropoly/fun/advent/01-1''\n",
      "\u001b[1;31m\n",
      "\u001b[1;31mFailed to run jupyter as observable with args notebook --no-browser --notebook-dir=\"/Users/mathieuboudreau/neuropoly/fun/advent/01-1\" --config=/var/folders/l1/1xswjffd73l8yp7dd7pq9lyw0000gn/T/aa7f2ece-3d62-4baf-ae26-3dd5604cf53a/jupyter_notebook_config.py --NotebookApp.iopub_data_rate_limit=10000000000.0"
     ]
    }
   ],
   "source": [
    "## Print solution\n",
    "\n",
    "print(sum(max_sums))"
   ]
  }
 ],
 "metadata": {
  "kernelspec": {
   "display_name": "Python 3.8.8 ('base')",
   "language": "python",
   "name": "python3"
  },
  "language_info": {
   "name": "python",
   "version": "3.8.8"
  },
  "orig_nbformat": 4,
  "vscode": {
   "interpreter": {
    "hash": "7b6a1e6c18d33edc8789944742c8a86446c3dbacb192990ec4f19dd1ca3f62b7"
   }
  }
 },
 "nbformat": 4,
 "nbformat_minor": 2
}
